<sdf version='1.6'>
  <world name='default'>
    <physics name='default_physics' default='0' type='ode'>
      <max_step_size>0.001</max_step_size>
      <real_time_factor>1</real_time_factor>
      <real_time_update_rate>1000</real_time_update_rate>
    </physics>
    <light name='sun' type='directional'>
      <cast_shadows>1</cast_shadows>
      <pose frame=''>0 0 10 0 -0 0</pose>
      <diffuse>0.8 0.8 0.8 1</diffuse>
      <specular>0.2 0.2 0.2 1</specular>
      <attenuation>
        <range>1000</range>
        <constant>0.9</constant>
        <linear>0.01</linear>
        <quadratic>0.001</quadratic>
      </attenuation>
      <direction>-0.5 0.1 -0.9</direction>
    </light>
    <model name='ground_plane'>
      <static>1</static>
      <link name='link'>
        <collision name='collision'>
          <geometry>
            <plane>
              <normal>0 0 1</normal>
              <size>100 100</size>
            </plane>
          </geometry>
          <surface>
            <contact>
              <collide_bitmask>65535</collide_bitmask>
              <ode/>
            </contact>
            <friction>
              <ode>
                <mu>100</mu>
                <mu2>50</mu2>
              </ode>
              <torsional>
                <ode/>
              </torsional>
            </friction>
            <bounce/>
          </surface>
          <max_contacts>10</max_contacts>
        </collision>
        <visual name='visual'>
          <cast_shadows>0</cast_shadows>
          <geometry>
            <plane>
              <normal>0 0 1</normal>
              <size>100 100</size>
            </plane>
          </geometry>
          <material>
            <script>
              <uri>file://media/materials/scripts/gazebo.material</uri>
              <name>Gazebo/Grey</name>
            </script>
          </material>
        </visual>
        <self_collide>0</self_collide>
        <kinematic>0</kinematic>
      </link>
    </model>
    <gravity>0 0 -9.8</gravity>
    <magnetic_field>6e-06 2.3e-05 -4.2e-05</magnetic_field>
    <atmosphere type='adiabatic'/>
    <scene>
      <ambient>0.4 0.4 0.4 1</ambient>
      <background>0.7 0.7 0.7 1</background>
      <shadows>1</shadows>
    </scene>
    <spherical_coordinates>
      <surface_model>EARTH_WGS84</surface_model>
      <latitude_deg>0</latitude_deg>
      <longitude_deg>0</longitude_deg>
      <elevation>0</elevation>
      <heading_deg>0</heading_deg>
    </spherical_coordinates>
    <model name='door'>
      <pose frame=''>2.98718 -0.808882 0 1.5708 -0 0</pose>
      <link name='door_frame'>
        <inertial>
          <pose frame=''>0.525 1 0.05 0 -0 0</pose>
          <mass>30</mass>
          <inertia>
            <ixx>1</ixx>
            <ixy>0</ixy>
            <ixz>0</ixz>
            <iyy>1</iyy>
            <iyz>0</iyz>
            <izz>1</izz>
          </inertia>
        </inertial>
        <visual name='visual_frame'>
          <pose frame=''>0 0 0 0 -0 0</pose>
          <geometry>
            <mesh>
              <uri>model://door/meshes/frame.stl</uri>
              <scale>0.1 0.1 0.1</scale>
            </mesh>
          </geometry>
        </visual>
        <collision name='collision_door'>
          <pose frame=''>0 0 0 0 -0 0</pose>
          <geometry>
            <mesh>
              <uri>model://door/meshes/frame.stl</uri>
              <scale>0.1 0.1 0.1</scale>
            </mesh>
          </geometry>
          <max_contacts>10</max_contacts>
          <surface>
            <contact>
              <ode/>
            </contact>
            <bounce/>
            <friction>
              <torsional>
                <ode/>
              </torsional>
              <ode/>
            </friction>
          </surface>
        </collision>
        <self_collide>0</self_collide>
        <kinematic>0</kinematic>
      </link>
      <link name='door_body'>
        <inertial>
          <pose frame=''>0.525 1 0.05 0 -0 0</pose>
          <mass>1</mass>
          <inertia>
            <ixx>0.083</ixx>
            <ixy>0</ixy>
            <ixz>0</ixz>
            <iyy>0.083</iyy>
            <iyz>0</iyz>
            <izz>0.083</izz>
          </inertia>
        </inertial>
        <collision name='collision_door'>
          <pose frame=''>0.525 0.995 0.05 0 -0 0</pose>
          <geometry>
            <box>
              <size>0.9 1.99 0.03</size>
            </box>
          </geometry>
          <max_contacts>10</max_contacts>
          <surface>
            <contact>
              <ode/>
            </contact>
            <bounce/>
            <friction>
              <torsional>
                <ode/>
              </torsional>
              <ode/>
            </friction>
          </surface>
        </collision>
        <visual name='visual_door'>
          <pose frame=''>0.525 0.995 0.05 0 -0 0</pose>
          <geometry>
            <box>
              <size>0.9 1.99 0.03</size>
            </box>
          </geometry>
        </visual>
        <self_collide>0</self_collide>
        <kinematic>0</kinematic>
      </link>
      <link name='door_handle'>
        <inertial>
          <pose frame=''>0.85 1 0.15 -3.14159 -0 0</pose>
          <mass>1</mass>
          <inertia>
            <ixx>1</ixx>
            <ixy>0</ixy>
            <ixz>0</ixz>
            <iyy>1</iyy>
            <iyz>0</iyz>
            <izz>1</izz>
          </inertia>
        </inertial>
        <visual name='visual_handle'>
          <pose frame=''>0.85 1 0.15 -3.14159 -0 0</pose>
          <geometry>
            <mesh>
              <uri>model://door/meshes/handle.stl</uri>
              <scale>0.002 0.002 0.002</scale>
            </mesh>
          </geometry>
        </visual>
        <collision name='collision_door'>
          <pose frame=''>0.85 1 0.15 -3.14159 -0 0</pose>
          <geometry>
            <mesh>
              <uri>model://door/meshes/handle.stl</uri>
              <scale>0.002 0.002 0.002</scale>
            </mesh>
          </geometry>
          <max_contacts>10</max_contacts>
          <surface>
            <contact>
              <ode/>
            </contact>
            <bounce/>
            <friction>
              <torsional>
                <ode/>
              </torsional>
              <ode/>
            </friction>
          </surface>
        </collision>
        <self_collide>0</self_collide>
        <kinematic>0</kinematic>
      </link>
      <joint name='handle_joint' type='revolute'>
        <child>door_handle</child>
        <parent>door_body</parent>
        <axis>
          <limit>
            <lower>0</lower>
            <upper>0</upper>
          </limit>
          <xyz>0 1 0</xyz>
          <dynamics>
            <damping>1</damping>
            <spring_reference>0</spring_reference>
            <spring_stiffness>0</spring_stiffness>
          </dynamics>
          <use_parent_model_frame>1</use_parent_model_frame>
          <use_parent_model_frame>1</use_parent_model_frame>
        </axis>
        <physics>
          <ode>
            <cfm_damping>1</cfm_damping>
            <limit>
              <cfm>0</cfm>
              <erp>0.2</erp>
            </limit>
          </ode>
        </physics>
      </joint>
      <joint name='door_hinge' type='revolute'>
        <parent>door_frame</parent>
        <child>door_body</child>
        <pose frame=''>0.075 0 0.065 0 -0 0</pose>
        <axis>
          <xyz>0 1 0</xyz>
          <dynamics>
            <damping>0.1</damping>
            <friction>0.1</friction>
            <spring_reference>0</spring_reference>
            <spring_stiffness>0</spring_stiffness>
          </dynamics>
          <limit>
            <lower>-1.57</lower>
            <upper>0</upper>
          </limit>
          <use_parent_model_frame>1</use_parent_model_frame>
        </axis>
      </joint>
      <joint name='world_joint' type='revolute'>
        <child>door_frame</child>
        <parent>world</parent>
        <axis>
          <limit>
            <lower>0</lower>
            <upper>0</upper>
          </limit>
          <xyz>0 1 0</xyz>
          <dynamics>
            <damping>1</damping>
            <spring_reference>0</spring_reference>
            <spring_stiffness>0</spring_stiffness>
          </dynamics>
          <use_parent_model_frame>1</use_parent_model_frame>
          <use_parent_model_frame>1</use_parent_model_frame>
        </axis>
        <physics>
          <ode>
            <cfm_damping>1</cfm_damping>
            <limit>
              <cfm>0</cfm>
              <erp>0.2</erp>
            </limit>
          </ode>
        </physics>
      </joint>
    </model>
    <state world_name='default'>
      <sim_time>45 70000000</sim_time>
      <real_time>45 342826522</real_time>
      <wall_time>1572878803 818439398</wall_time>
      <iterations>45070</iterations>
      <model name='door'>
        <pose frame=''>2.98718 -0.808882 1e-06 1.5708 -0 0</pose>
        <scale>1 1 1</scale>
        <link name='door_body'>
          <pose frame=''>2.9874 -0.808621 2e-06 1.5708 1e-06 -0.003489</pose>
          <velocity>0.000147 -1.8e-05 -8.2e-05 -5e-06 -2.8e-05 -0.000188</velocity>
          <acceleration>0.216493 -0.145064 -0.13318 -0.010182 -0.056019 -0.186003</acceleration>
          <wrench>0.216493 -0.145064 -0.13318 0 -0 0</wrench>
        </link>
        <link name='door_frame'>
          <pose frame=''>2.98718 -0.808882 1e-06 1.5708 -0 0</pose>
          <velocity>-1e-06 -2e-06 -4e-06 4e-06 1.6e-05 1e-06</velocity>
          <acceleration>0.030276 -0.011024 -0.025787 0.00876 0.030951 0.001908</acceleration>
          <wrench>0.908279 -0.33071 -0.773616 0 -0 0</wrench>
        </link>
        <link name='door_handle'>
          <pose frame=''>2.9874 -0.808621 2e-06 1.5708 -0 -0.003489</pose>
          <velocity>0.000196 -3.9e-05 -0.000126 -2e-06 6e-06 -9e-06</velocity>
          <acceleration>0.410235 0.015613 -0.26085 -0.005023 0.011013 0.135515</acceleration>
          <wrench>0.410235 0.015613 -0.26085 0 -0 0</wrench>
        </link>
      </model>
      <model name='ground_plane'>
        <pose frame=''>0 0 0 0 -0 0</pose>
        <scale>1 1 1</scale>
        <link name='link'>
          <pose frame=''>0 0 0 0 -0 0</pose>
          <velocity>0 0 0 0 -0 0</velocity>
          <acceleration>0 0 0 0 -0 0</acceleration>
          <wrench>0 0 0 0 -0 0</wrench>
        </link>
      </model>
      <light name='sun'>
        <pose frame=''>0 0 10 0 -0 0</pose>
      </light>
    </state>
    <gui fullscreen='0'>
      <camera name='user_camera'>
        <pose frame=''>7.17823 -2.82111 1.95359 0 0.275643 2.62019</pose>
        <view_controller>orbit</view_controller>
        <projection_type>perspective</projection_type>
      </camera>
    </gui>
  </world>
</sdf>
